<mujoco model="panda_dual">
  <compiler angle="radian" meshdir="assets" autolimits="true"/>

  <option integrator="implicitfast"/>

  <default>
    <default class="panda_dual">
      <material specular="0.5" shininess="0.25"/>
      <joint armature="0.1" damping="1" axis="0 0 1" range="-2.8973 2.8973"/>
      <general dyntype="none" biastype="affine" ctrlrange="-2.8973 2.8973" forcerange="-87 87"/>
      <default class="finger_dual">
        <joint axis="0 1 0" type="slide" range="0 0.04"/>
      </default>

      <default class="visual_dual">
        <geom type="mesh" contype="0" conaffinity="0" group="2"/>
      </default>
      <default class="collision_dual">
        <geom type="mesh" group="3"/>
        <default class="fingertip_pad_collision_1">
          <geom type="box" size="0.0085 0.004 0.0085" pos="0 0.0055 0.0445"/>
        </default>
        <default class="fingertip_pad_collision_2">
          <geom type="box" size="0.003 0.002 0.003" pos="0.0055 0.002 0.05"/>
        </default>
        <default class="fingertip_pad_collision_3">
          <geom type="box" size="0.003 0.002 0.003" pos="-0.0055 0.002 0.05"/>
        </default>
        <default class="fingertip_pad_collision_4">
          <geom type="box" size="0.003 0.002 0.0035" pos="0.0055 0.002 0.0395"/>
        </default>
        <default class="fingertip_pad_collision_5">
          <geom type="box" size="0.003 0.002 0.0035" pos="-0.0055 0.002 0.0395"/>
        </default>
      </default>
    </default>
  </default>

  <asset>
    <material class="panda_dual" name="white_dual" rgba="1 1 1 1"/>
    <material class="panda_dual" name="off_white_dual" rgba="0.901961 0.921569 0.929412 1"/>
    <material class="panda_dual" name="black" rgba="0.25 0.25 0.25 1"/>
    <material class="panda_dual" name="green_dual" rgba="0 1 0 1"/>
    <material class="panda_dual" name="light_blue_dual" rgba="0.039216 0.541176 0.780392 1"/>

    <!-- Collision meshes -->
    <mesh name="link0_c_dual" file="link0.stl"/>
    <mesh name="link1_c_dual" file="link1.stl"/>
    <mesh name="link2_c_dual" file="link2.stl"/>
    <mesh name="link3_c_dual" file="link3.stl"/>
    <mesh name="link4_c_dual" file="link4.stl"/>
    <mesh name="link5_c0_dual" file="link5_collision_0.obj"/>
    <mesh name="link5_c1_dual" file="link5_collision_1.obj"/>
    <mesh name="link5_c2_dual" file="link5_collision_2.obj"/>
    <mesh name="link6_c_dual" file="link6.stl"/>
    <mesh name="link7_c_dual" file="link7.stl"/>
    <mesh name="hand_c_dual" file="hand.stl"/>

    <!-- Visual meshes -->
    <mesh name="link0_0_dual" file="link0_0.obj"/>
    <mesh name="link0_1_dual" file="link0_1.obj"/>
    <mesh name="link0_2_dual" file="link0_2.obj"/>
    <mesh name="link0_3_dual" file="link0_3.obj"/>
    <mesh name="link0_4_dual" file="link0_4.obj"/>
    <mesh name="link0_5_dual" file="link0_5.obj"/>
    <mesh name="link0_7_dual" file="link0_7.obj"/>
    <mesh name="link0_8_dual" file="link0_8.obj"/>
    <mesh name="link0_9_dual" file="link0_9.obj"/>
    <mesh name="link0_10_dual" file="link0_10.obj"/>
    <mesh name="link0_11_dual" file="link0_11.obj"/>
    <mesh name="link1_dual" file="link1.obj"/>
    <mesh name="link2_dual" file="link2.obj"/>
    <mesh name="link3_0_dual" file="link3_0.obj"/>
    <mesh name="link3_1_dual" file="link3_1.obj"/>
    <mesh name="link3_2_dual" file="link3_2.obj"/>
    <mesh name="link3_3_dual" file="link3_3.obj"/>
    <mesh name="link4_0_dual" file="link4_0.obj"/>
    <mesh name="link4_1_dual" file="link4_1.obj"/>
    <mesh name="link4_2_dual" file="link4_2.obj"/>
    <mesh name="link4_3_dual" file="link4_3.obj"/>
    <mesh name="link5_0_dual" file="link5_0.obj"/>
    <mesh name="link5_1_dual" file="link5_1.obj"/>
    <mesh name="link5_2_dual" file="link5_2.obj"/>
    <mesh name="link6_0_dual" file="link6_0.obj"/>
    <mesh name="link6_1_dual" file="link6_1.obj"/>
    <mesh name="link6_2_dual" file="link6_2.obj"/>
    <mesh name="link6_3_dual" file="link6_3.obj"/>
    <mesh name="link6_4_dual" file="link6_4.obj"/>
    <mesh name="link6_5_dual" file="link6_5.obj"/>
    <mesh name="link6_6_dual" file="link6_6.obj"/>
    <mesh name="link6_7_dual" file="link6_7.obj"/>
    <mesh name="link6_8_dual" file="link6_8.obj"/>
    <mesh name="link6_9_dual" file="link6_9.obj"/>
    <mesh name="link6_10_dual" file="link6_10.obj"/>
    <mesh name="link6_11_dual" file="link6_11.obj"/>
    <mesh name="link6_12_dual" file="link6_12.obj"/>
    <mesh name="link6_13_dual" file="link6_13.obj"/>
    <mesh name="link6_14_dual" file="link6_14.obj"/>
    <mesh name="link6_15_dual"  file="link6_15.obj"/>
    <mesh name="link6_16_dual" file="link6_16.obj"/>
    <mesh name="link7_0_dual" file="link7_0.obj"/>
    <mesh name="link7_1_dual" file="link7_1.obj"/>
    <mesh name="link7_2_dual" file="link7_2.obj"/>
    <mesh name="link7_3_dual" file="link7_3.obj"/>
    <mesh name="link7_4_dual" file="link7_4.obj"/>
    <mesh name="link7_5_dual" file="link7_5.obj"/>
    <mesh name="link7_6_dual" file="link7_6.obj"/>
    <mesh name="link7_7_dual" file="link7_7.obj"/>
    <mesh name="hand_0_dual" file="hand_0.obj"/>
    <mesh name="hand_1_dual" file="hand_1.obj"/>
    <mesh name="hand_2_dual" file="hand_2.obj"/>
    <mesh name="hand_3_dual" file="hand_3.obj"/>
    <mesh name="hand_4_dual" file="hand_4.obj"/>
    <mesh name="finger_0_dual" file="finger_0.obj"/>
    <mesh name="finger_1_dual" file="finger_1.obj"/>
  </asset>

  <worldbody>
    <!-- <light name="top" pos="0 0 2" mode="trackcom"/> -->
    <body name="link0_dual" pos="0.7 0.75 0.015" euler="0 0 -1.57" childclass="panda_dual" gravcomp="1">
      <inertial mass="0.629769" pos="-0.041018 -0.00014 0.049974"
        fullinertia="0.00315 0.00388 0.004285 8.2904e-7 0.00015 8.2299e-6"/>
      <geom mesh="link0_0_dual" material="off_white_dual" class="visual_dual"/>
      <geom mesh="link0_1_dual" material="black" class="visual_dual"/>
      <geom mesh="link0_2_dual" material="off_white_dual" class="visual_dual"/>
      <geom mesh="link0_3_dual" material="black" class="visual_dual"/>
      <geom mesh="link0_4_dual" material="off_white_dual" class="visual_dual"/>
      <geom mesh="link0_5_dual" material="black" class="visual_dual"/>
      <geom mesh="link0_7_dual" material="white_dual" class="visual_dual"/>
      <geom mesh="link0_8_dual" material="white_dual" class="visual_dual"/>
      <geom mesh="link0_9_dual" material="black" class="visual_dual"/>
      <geom mesh="link0_10_dual" material="off_white_dual" class="visual_dual"/>
      <geom mesh="link0_11_dual" material="white_dual" class="visual_dual"/>
      <geom mesh="link0_c_dual" class="collision_dual"/>
      <body name="link1_dual" pos="0 0 0.333" gravcomp="1">
        <inertial mass="4.970684" pos="0.003875 0.002081 -0.04762"
          fullinertia="0.70337 0.70661 0.0091170 -0.00013900 0.0067720 0.019169"/>
        <joint name="joint1_dual"/>
        <geom material="white_dual" mesh="link1" class="visual_dual"/>
        <geom mesh="link1_c_dual" class="collision_dual"/>
        <body name="link2_dual" quat="1 -1 0 0" gravcomp="1">
          <inertial mass="0.646926" pos="-0.003141 -0.02872 0.003495"
            fullinertia="0.0079620 2.8110e-2 2.5995e-2 -3.925e-3 1.0254e-2 7.04e-4"/>
          <joint name="joint2_dual" range="-1.7628 1.7628"/>
          <geom material="white_dual" mesh="link2" class="visual_dual"/>
          <geom mesh="link2_c_dual" class="collision_dual"/>
          <body name="link3_dual" pos="0 -0.316 0" quat="1 1 0 0" gravcomp="1">
            <joint name="joint3_dual"/>
            <inertial mass="3.228604" pos="2.7518e-2 3.9252e-2 -6.6502e-2"
              fullinertia="3.7242e-2 3.6155e-2 1.083e-2 -4.761e-3 -1.1396e-2 -1.2805e-2"/>
            <geom mesh="link3_0_dual" material="white_dual" class="visual_dual"/>
            <geom mesh="link3_1_dual" material="white_dual" class="visual_dual"/>
            <geom mesh="link3_2_dual" material="white_dual" class="visual_dual"/>
            <geom mesh="link3_3_dual" material="black" class="visual_dual"/>
            <geom mesh="link3_c_dual" class="collision_dual"/>
            <body name="link4_dual" pos="0.0825 0 0" quat="1 1 0 0" gravcomp="1">
              <inertial mass="3.587895" pos="-5.317e-2 1.04419e-1 2.7454e-2"
                fullinertia="2.5853e-2 1.9552e-2 2.8323e-2 7.796e-3 -1.332e-3 8.641e-3"/>
              <joint name="joint4_dual" range="-3.0718 -0.0698"/>
              <geom mesh="link4_0_dual" material="white_dual" class="visual_dual"/>
              <geom mesh="link4_1_dual" material="white_dual" class="visual_dual"/>
              <geom mesh="link4_2_dual" material="black" class="visual_dual"/>
              <geom mesh="link4_3_dual" material="white_dual" class="visual_dual"/>
              <geom mesh="link4_c_dual" class="collision_dual"/>
              <body name="link5_dual" pos="-0.0825 0.384 0" quat="1 -1 0 0" gravcomp="1">
                <inertial mass="1.225946" pos="-1.1953e-2 4.1065e-2 -3.8437e-2"
                  fullinertia="3.5549e-2 2.9474e-2 8.627e-3 -2.117e-3 -4.037e-3 2.29e-4"/>
                <joint name="joint5_dual"/>
                <geom mesh="link5_0_dual" material="black" class="visual_dual"/>
                <geom mesh="link5_1_dual" material="white_dual" class="visual_dual"/>
                <geom mesh="link5_2_dual" material="white_dual" class="visual_dual"/>
                <geom mesh="link5_c0_dual" class="collision_dual"/>
                <geom mesh="link5_c1_dual" class="collision_dual"/>
                <geom mesh="link5_c2_dual" class="collision_dual"/>
                <body name="link6_dual" quat="1 1 0 0" gravcomp="1">
                  <inertial mass="1.666555" pos="6.0149e-2 -1.4117e-2 -1.0517e-2"
                    fullinertia="1.964e-3 4.354e-3 5.433e-3 1.09e-4 -1.158e-3 3.41e-4"/>
                  <joint name="joint6_dual" range="-0.0175 3.7525"/>
                  <geom mesh="link6_0_dual" material="off_white_dual" class="visual_dual"/>
                  <geom mesh="link6_1_dual" material="white_dual" class="visual_dual"/>
                  <geom mesh="link6_2_dual" material="black" class="visual_dual"/>
                  <geom mesh="link6_3_dual" material="white_dual" class="visual_dual"/>
                  <geom mesh="link6_4_dual" material="white_dual" class="visual_dual"/>
                  <geom mesh="link6_5_dual" material="white_dual" class="visual_dual"/>
                  <geom mesh="link6_6_dual" material="white_dual" class="visual_dual"/>
                  <geom mesh="link6_7_dual" material="light_blue_dual" class="visual_dual"/>
                  <geom mesh="link6_8_dual" material="light_blue_dual" class="visual_dual"/>
                  <geom mesh="link6_9_dual" material="black" class="visual_dual"/>
                  <geom mesh="link6_10_dual" material="black" class="visual_dual"/>
                  <geom mesh="link6_11_dual" material="white_dual" class="visual_dual"/>
                  <geom mesh="link6_12_dual" material="green_dual" class="visual_dual"/>
                  <geom mesh="link6_13_dual" material="white_dual" class="visual_dual"/>
                  <geom mesh="link6_14_dual" material="black" class="visual_dual"/>
                  <geom mesh="link6_15_dual" material="black" class="visual_dual"/>
                  <geom mesh="link6_16_dual" material="white_dual" class="visual_dual"/>
                  <geom mesh="link6_c_dual" class="collision_dual"/>
                  <body name="link7_dual" pos="0.088 0 0" quat="1 1 0 0" gravcomp="1">
                    <inertial mass="7.35522e-01" pos="1.0517e-2 -4.252e-3 6.1597e-2"
                      fullinertia="1.2516e-2 1.0027e-2 4.815e-3 -4.28e-4 -1.196e-3 -7.41e-4"/>
                    <joint name="joint7_dual"/>
                    <geom mesh="link7_0_dual" material="white_dual" class="visual_dual"/>
                    <geom mesh="link7_1_dual" material="black" class="visual_dual"/>
                    <geom mesh="link7_2_dual" material="black" class="visual_dual"/>
                    <geom mesh="link7_3_dual" material="black" class="visual_dual"/>
                    <geom mesh="link7_4_dual" material="black" class="visual_dual"/>
                    <geom mesh="link7_5_dual" material="black" class="visual_dual"/>
                    <geom mesh="link7_6_dual" material="black" class="visual_dual"/>
                    <geom mesh="link7_7_dual" material="white_dual" class="visual_dual"/>
                    <geom mesh="link7_c_dual" class="collision_dual"/>
                    <body name="hand" pos="0 0 0.107" quat="0.9238795 0 0 -0.3826834" gravcomp="1">
                      <inertial mass="0.73" pos="-0.01 0 0.03" diaginertia="0.001 0.0025 0.0017"/>
                      <site name="tcp_site_dual" pos="0 0 0.107" size="0.01" rgba="0 0 1 0"/>
                      <geom mesh="hand_0_dual" material="off_white_dual" class="visual_dual"/>
                      <geom mesh="hand_1_dual" material="black" class="visual_dual"/>
                      <geom mesh="hand_2_dual" material="black" class="visual_dual"/>
                      <geom mesh="hand_3_dual" material="white_dual" class="visual_dual"/>
                      <geom mesh="hand_4_dual" material="off_white_dual" class="visual_dual"/>
                      <geom mesh="hand_c_dual" class="collision_dual"/>
                      <body name="left_finger_dual" pos="0 0 0.0584" gravcomp="1">
                        <inertial mass="0.015" pos="0 0 0" diaginertia="2.375e-6 2.375e-6 7.5e-7"/>
                        <joint name="finger_joint1" class="finger_dual"/>
                        <geom mesh="finger_0_dual" material="off_white_dual" class="visual_dual"/>
                        <geom mesh="finger_1_dual" material="black" class="visual_dual"/>
                        <geom mesh="finger_0_dual" class="collision_dual"/>
                        <geom name="ltip_col1" class="fingertip_pad_collision_1"/>
                        <geom name="ltip_col2" class="fingertip_pad_collision_2"/>
                        <geom name="ltip_col3" class="fingertip_pad_collision_3"/>
                        <geom name="ltip_col4" class="fingertip_pad_collision_4"/>
                        <geom name="ltip_col5" class="fingertip_pad_collision_5"/>
                      </body>
                      <body name="right_finger_dual" pos="0 0 0.0584" quat="0 0 0 1" gravcomp="1">
                        <inertial mass="0.015" pos="0 0 0" diaginertia="2.375e-6 2.375e-6 7.5e-7"/>
                        <joint name="finger_joint2" class="finger_dual"/>
                        <geom mesh="finger_0_dual" material="off_white_dual" class="visual_dual"/>
                        <geom mesh="finger_1_dual" material="black" class="visual_dual"/>
                        <geom mesh="finger_0_dual" class="collision_dual"/>
                        <geom name="rtip_col1" class="fingertip_pad_collision_1" rgba="1 0 0 1"/>
                        <geom name="rtip_col2" class="fingertip_pad_collision_2"/>
                        <geom name="rtip_col3" class="fingertip_pad_collision_3"/>
                        <geom name="rtip_col4" class="fingertip_pad_collision_4"/>
                        <geom name="rtip_col5" class="fingertip_pad_collision_5"/>
                      </body>
                    </body>
                  </body>
                </body>
              </body>
            </body>
          </body>
        </body>
      </body>
    </body>
  </worldbody>

  <tendon>
    <fixed name="split_dual">
      <joint joint="finger_joint1" coef="0.5"/>
      <joint joint="finger_joint2" coef="0.5"/>
    </fixed>
  </tendon>

  <equality>
    <joint joint1="finger_joint1" joint2="finger_joint2" solimp="0.95 0.99 0.001" solref="0.005 1"/>
  </equality>

</mujoco>
