<mujoco model="ur5e">
  <compiler angle="radian" meshdir="assets" autolimits="true"/>
  
  <option cone="elliptic" impratio="10"/>

  <default>
    <default class="ur5e">
      <joint axis="0 1 0" range="-6.28319 6.28319"/>
      <position ctrlrange="-6.28319 6.28319"/>
      <!-- <general ctrlrange="-6.28319 6.28319"/> -->

      <default class="visual_ur5e">
        <geom type="mesh" contype="0" conaffinity="0" group="2"/>
      </default>
      <default class="collision_ur5e">
        <geom type="capsule" group="3"/>
        <default class="eef_collision">
          <geom type="cylinder"/>
        </default>
      </default>
      <site size="0.001" rgba="0.5 0.5 0.5 0.3" group="4"/>

      <!-- Reference:
        https://www.universal-robots.com/articles/ur/robot-care-maintenance/max-joint-torques/ -->
      <default class="size3">
        <joint armature="0.1" damping="200"/>
        <!-- <general biastype="affine"/> -->
        <position kp="3500" forcerange="-150 150"/>
        <default class="size3_limited">
          <joint range="-3.1415 3.1415"/>
          <position ctrlrange="-3.1415 3.1415"/>
          <!-- <general ctrlrange="-3.1415 3.1415"/> -->
        </default>
      </default>
      <default class="size1">
        <joint armature="0.1" damping="15"/>
        <!-- <general
          biastype="affine"
          gainprm="350 0 0"
          biasprm="0 -350 0"
          forcerange="-40 40"/> -->
        <position kp="3000" forcerange="-28 28"/>
      </default>
    </default>

    <!-- dex -->
    <default class="allegro_left">
      <joint axis="0 1 0" damping=".1"/>
      <position kp="1"/>
      <geom density="800"/>

      <default class="visual">
        <geom type="mesh" contype="0" conaffinity="0" group="2" material="black"/>
        <default class="palm_visual">
          <geom mesh="base_link"/>
        </default>
        <default class="base_visual">
          <geom mesh="link_0.0"/>
        </default>
        <default class="proximal_visual">
          <geom mesh="link_1.0"/>
        </default>
        <default class="medial_visual">
          <geom mesh="link_2.0"/>
        </default>
        <default class="distal_visual">
          <geom mesh="link_3.0"/>
        </default>
        <default class="fingertip_visual">
          <geom pos="0 0 0.0267" material="white" mesh="link_3.0_tip"/>
        </default>
        <default class="thumbtip_visual">
          <geom pos="0 0 0.0423" material="white" mesh="link_15.0_tip"/>
        </default>
      </default>

      <default class="collision">
        <geom group="3" type="box" mass="0"/>
        <default class="palm_collision">
          <geom size="0.0204 0.0565 0.0475" pos="-0.0093 0 -0.0475"/>
        </default>
        <default class="base_collision">
          <geom size="0.0098 0.01375 0.0082" pos="0 0 0.0082"/>
          <default class="thumb_base_collision">
            <geom size="0.0179 0.017 0.02275" pos="-0.0179 0.009 0.0145"/>
          </default>
        </default>
        <default class="proximal_collision">
          <geom size="0.0098 0.01375 0.027" pos="0 0 0.027"/>
          <default class="thumb_proximal_collision">
            <geom size="0.0098 0.01375 0.00885" pos="0 0 0.00885"/>
          </default>
        </default>
        <default class="medial_collision">
          <geom size="0.0098 0.01375 0.0192" pos="0 0 0.0192"/>
          <default class="thumb_medial_collision">
            <geom size="0.0098 0.01375 0.0257" pos="0 0 0.0257"/>
          </default>
        </default>
        <default class="distal_collision">
          <geom size="0.0098 0.01375 0.008" pos="0 0 0.008"/>
          <default class="thumb_distal_collision">
            <geom size="0.0098 0.01375 0.0157" pos="0 0 0.0157"/>
          </default>
        </default>
        <default class="fingertip_collision">
          <geom type="capsule" size="0.012 0.01" pos="0 0 0.019"/>
          <default class="thumbtip_collision">
            <geom type="capsule" size="0.012 0.008" pos="0 0 0.035"/>
          </default>
        </default>
      </default>

      <default class="base">
        <joint axis="0 0 1" range="-0.47 0.47"/>
        <position ctrlrange="-0.47 0.47"/>
      </default>
      <default class="proximal">
        <joint range="-0.196 1.61"/>
        <position ctrlrange="-0.196 1.61"/>
      </default>
      <default class="medial">
        <joint range="-0.174 1.709"/>
        <position ctrlrange="-0.174 1.709"/>
      </default>
      <default class="distal">
        <joint range="-0.227 1.618"/>
        <position ctrlrange="-0.227 1.618"/>
      </default>
      <default class="thumb_base">
        <joint axis="1 0 0" range="0.263 1.396"/>
        <position ctrlrange="0.263 1.396"/>
      </default>
      <default class="thumb_proximal">
        <joint axis="0 0 -1" range="-0.105 1.163"/>
        <position ctrlrange="-0.105 1.163"/>
      </default>
      <default class="thumb_medial">
        <joint range="-0.189 1.644"/>
        <position ctrlrange="-0.189 1.644"/>
      </default>
      <default class="thumb_distal">
        <joint range="-0.162 1.719"/>
        <position ctrlrange="-0.162 1.719"/>
      </default>
    </default>
  
  </default>

  <asset>
    <material name="black_ur5e" specular="0.5" shininess="0.25" rgba="0.033 0.033 0.033 1"/>
    <material name="jointgray" specular="0.5" shininess="0.25" rgba="0.278 0.278 0.278 1"/>
    <material name="linkgray" specular="0.5" shininess="0.25" rgba="0.82 0.82 0.82 1"/>
    <material name="urblue" specular="0.5" shininess="0.25" rgba="0.49 0.678 0.8 1"/>
    <!-- dex -->
    <material name="black" rgba="0.2 0.2 0.2 1"/>
    <material name="white" rgba="0.9 0.9 0.9 1"/>

    <mesh file="base_0.obj"/>
    <mesh file="base_1.obj"/>
    <mesh file="shoulder_0.obj"/>
    <mesh file="shoulder_1.obj"/>
    <mesh file="shoulder_2.obj"/>
    <mesh file="upperarm_0.obj"/>
    <mesh file="upperarm_1.obj"/>
    <mesh file="upperarm_2.obj"/>
    <mesh file="upperarm_3.obj"/>
    <mesh file="forearm_0.obj"/>
    <mesh file="forearm_1.obj"/>
    <mesh file="forearm_2.obj"/>
    <mesh file="forearm_3.obj"/>
    <mesh file="wrist1_0.obj"/>
    <mesh file="wrist1_1.obj"/>
    <mesh file="wrist1_2.obj"/>
    <mesh file="wrist2_0.obj"/>
    <mesh file="wrist2_1.obj"/>
    <mesh file="wrist2_2.obj"/>
    <mesh file="wrist3.obj"/>
    <!-- dex -->
    <mesh file="base_link_left.stl"/>
    <mesh file="link_0.0.stl"/>
    <mesh file="link_1.0.stl"/>
    <mesh file="link_2.0.stl"/>
    <mesh file="link_3.0.stl"/>
    <mesh file="link_3.0_tip.stl"/>
    <mesh file="link_12.0_left.stl"/>
    <mesh file="link_13.0.stl"/>
    <mesh file="link_14.0.stl"/>
    <mesh file="link_15.0.stl"/>
    <mesh file="link_15.0_tip.stl"/>
  </asset>

  <worldbody>
    <!-- <light name="spotlight" mode="targetbodycom" target="wrist_2_link" pos="0 -1 2"/> -->
    <body name="base_ur5e" quat="0 0 0 0" childclass="ur5e" pos="0.1 0 -0.05" gravcomp="1">
      <inertial mass="4.0" pos="0 0 0" diaginertia="0.00443333156 0.00443333156 0.0072"/>
      <geom mesh="base_0" material="black_ur5e" class="visual_ur5e"/>
      <!-- <geom mesh="base_1" material="jointgray" class="visual_ur5e"/> -->
      <body name="shoulder_link" pos="0 0 0.163" gravcomp="1">
        <inertial mass="3.7" pos="0 0 0" diaginertia="0.0102675 0.0102675 0.00666"/>
        <joint name="shoulder_pan_joint" class="size3" axis="0 0 1"/>
        <geom mesh="shoulder_0" material="urblue" class="visual_ur5e"/>
        <geom mesh="shoulder_1" material="black_ur5e" class="visual_ur5e"/>
        <geom mesh="shoulder_2" material="jointgray" class="visual_ur5e"/>
        <geom class="collision_ur5e" size="0.06 0.02" pos="0 0 0.01"/>
        <body name="upper_arm_link" pos="0 0.138 0" quat="1 0 1 0" gravcomp="1">
          <inertial mass="8.393" pos="0 0 0.2125" diaginertia="0.133886 0.133886 0.0151074"/>
          <joint name="shoulder_lift_joint" class="size3"/>
          <geom mesh="upperarm_0" material="linkgray" class="visual_ur5e"/>
          <geom mesh="upperarm_1" material="black_ur5e" class="visual_ur5e"/>
          <geom mesh="upperarm_2" material="jointgray" class="visual_ur5e"/>
          <geom mesh="upperarm_3" material="urblue" class="visual_ur5e"/>
          <geom class="collision_ur5e" pos="0 -0.04 0" quat="1 1 0 0" size="0.06 0.06"/>
          <geom class="collision_ur5e" size="0.05 0.2" pos="0 0 0.2"/>
          <body name="forearm_link" pos="0 -0.131 0.425" gravcomp="1">
            <inertial mass="2.275" pos="0 0 0.196" diaginertia="0.0311796 0.0311796 0.004095"/>
            <joint name="elbow_joint" class="size3_limited"/>
            <geom mesh="forearm_0" material="urblue" class="visual_ur5e"/>
            <geom mesh="forearm_1" material="linkgray" class="visual_ur5e"/>
            <geom mesh="forearm_2" material="black_ur5e" class="visual_ur5e"/>
            <geom mesh="forearm_3" material="jointgray" class="visual_ur5e"/>
            <geom class="collision_ur5e" pos="0 0.08 0" quat="1 1 0 0" size="0.055 0.06"/>
            <geom class="collision_ur5e" size="0.038 0.19" pos="0 0 0.2"/>
            <body name="wrist_1_link" pos="0 0 0.392" quat="1 0 1 0" gravcomp="1">
              <inertial mass="1.219" pos="0 0.127 0" diaginertia="0.0025599 0.0025599 0.0021942"/>
              <joint name="wrist_1_joint" class="size1"/>
              <geom mesh="wrist1_0" material="black_ur5e" class="visual_ur5e"/>
              <geom mesh="wrist1_1" material="urblue" class="visual_ur5e"/>
              <geom mesh="wrist1_2" material="jointgray" class="visual_ur5e"/>
              <geom class="collision_ur5e" pos="0 0.05 0" quat="1 1 0 0" size="0.04 0.07"/>
              <body name="wrist_2_link" pos="0 0.127 0" gravcomp="1">
                <inertial mass="1.219" pos="0 0 0.1" diaginertia="0.0025599 0.0025599 0.0021942"/>
                <joint name="wrist_2_joint" axis="0 0 1" class="size1"/>
                <geom mesh="wrist2_0" material="black_ur5e" class="visual_ur5e"/>
                <geom mesh="wrist2_1" material="urblue" class="visual_ur5e"/>
                <geom mesh="wrist2_2" material="jointgray" class="visual_ur5e"/>
                <geom class="collision_ur5e" size="0.04 0.06" pos="0 0 0.04"/>
                <geom class="collision_ur5e" pos="0 0.02 0.1" quat="1 1 0 0" size="0.04 0.04"/>
                <body name="wrist_3_link" pos="0 0 0.1" gravcomp="1">
                  <inertial mass="0.1889" pos="0 0.0771683 0" quat="1 0 0 1"
                      diaginertia="0.000132134 9.90863e-05 9.90863e-05"/>
                  <joint name="wrist_3_joint" class="size1"/>
                  <geom material="linkgray" mesh="wrist3" class="visual_ur5e"/>
                  <geom class="eef_collision" pos="0 0.08 0" quat="1 1 0 0" size="0.04 0.02"/>
                  <site name="attachment_site" pos="0 0.1 0" quat="-1 1 0 0"/>

                  <!-- Dexterous right hand Allegro -->
                  <!-- quat="0 1 0 1" -->
                  <body name="palm" pos="0 0.13 0.045" quat="1 0 0 1" childclass="allegro_left" gravcomp="1">
                    <!-- <inertial mass="0.4154" pos="0 0 0.0475" diaginertia="1e-4 1e-4 1e-4"/> -->
                    <site name="tcp_site" type="box" pos="0.04 0 -0.02" size="0.01 0.02 0.01" rgba="1 0 0 0"/>
                    <body name="tcp_center" pos="0.04 0 -0.02"/>
                    <geom quat="1 -1 0 0" class="palm_visual" mesh="base_link_left"/>
                    <geom class="palm_collision"/>
                    <!-- Ring finger -->
                    <body name="rf_base" pos="0 0.0435 -0.001542" quat="0.999048 -0.0436194 0 0" gravcomp="1">
                      <joint name="rfj0" class="base"/>
                      <geom class="base_visual"/>
                      <geom class="base_collision"/>
                      <body name="rf_proximal" pos="0 0 0.0164" gravcomp="1">
                        <joint name="rfj1" class="proximal"/>
                        <geom class="proximal_visual"/>
                        <geom class="proximal_collision"/>
                        <body name="rf_medial" pos="0 0 0.054" gravcomp="1">
                          <joint name="rfj2" class="medial"/>
                          <geom class="medial_visual"/>
                          <geom class="medial_collision"/>
                          <body name="rf_distal" pos="0 0 0.0384" gravcomp="1">
                            <joint name="rfj3" class="distal"/>
                            <geom class="distal_visual"/>
                            <geom class="distal_collision"/>
                            <body name="rf_tip" gravcomp="1">
                              <geom class="fingertip_visual"/>
                              <geom class="fingertip_collision"/>
                            </body>
                          </body>
                        </body>
                      </body>
                    </body>
                    <!-- Middle finger -->
                    <body name="mf_base" pos="0 0 0.0007" gravcomp="1">
                      <joint name="mfj0" class="base"/>
                      <geom class="base_visual"/>
                      <geom class="base_collision"/>
                      <body name="mf_proximal" pos="0 0 0.0164" gravcomp="1">
                        <joint name="mfj1" class="proximal"/>
                        <geom class="proximal_visual"/>
                        <geom class="proximal_collision"/>
                        <body name="mf_medial" pos="0 0 0.054" gravcomp="1">
                          <joint name="mfj2" class="medial"/>
                          <geom class="medial_visual"/>
                          <geom class="medial_collision"/>
                          <body name="mf_distal" pos="0 0 0.0384" gravcomp="1">
                            <joint name="mfj3" class="distal"/>
                            <geom class="distal_visual"/>
                            <geom class="distal_collision"/>
                            <body name="mf_tip" gravcomp="1">
                              <geom class="fingertip_visual"/>
                              <geom class="fingertip_collision"/>
                            </body>
                          </body>
                        </body>
                      </body>
                    </body>
                    <!-- First finger -->
                    <body name="ff_base" pos="0 -0.0435 -0.001542" quat="0.999048 0.0436194 0 0" gravcomp="1">
                      <joint name="ffj0" class="base"/>
                      <geom class="base_visual"/>
                      <geom class="base_collision"/>
                      <body name="ff_proximal" pos="0 0 0.0164" gravcomp="1">
                        <joint name="ffj1" class="proximal"/>
                        <geom class="proximal_visual"/>
                        <geom class="proximal_collision"/>
                        <body name="ff_medial" pos="0 0 0.054" gravcomp="1">
                          <joint name="ffj2" class="medial"/>
                          <geom class="medial_visual"/>
                          <geom class="medial_collision"/>
                          <body name="ff_distal" pos="0 0 0.0384" gravcomp="1">
                            <joint name="ffj3" class="distal"/>
                            <geom class="distal_visual"/>
                            <geom class="distal_collision"/>
                            <body name="ff_tip" gravcomp="1">
                              <geom class="fingertip_visual"/>
                              <geom class="fingertip_collision"/>
                            </body>
                          </body>
                        </body>
                      </body>
                    </body>
                    <!-- Thumb -->
                    <body name="th_base" pos="-0.0182 -0.019333 -0.045987" quat="0.477714 0.521334 -0.521334 0.477714" gravcomp="1">
                      <joint name="thj0" class="thumb_base"/>
                      <geom quat="0 1 0 0" class="visual" mesh="link_12.0_left"/>
                      <geom class="thumb_base_collision"/>
                      <body name="th_proximal" pos="-0.027 -0.005 0.0399" gravcomp="1">
                        <joint name="thj1" class="thumb_proximal"/>
                        <geom class="visual" mesh="link_13.0"/>
                        <geom class="thumb_proximal_collision"/>
                        <body name="th_medial" pos="0 0 0.0177" gravcomp="1">
                          <joint name="thj2" class="thumb_medial"/>
                          <geom class="visual" mesh="link_14.0"/>
                          <geom class="thumb_medial_collision"/>
                          <body name="th_distal" pos="0 0 0.0514" gravcomp="1">
                            <joint name="thj3" class="thumb_distal"/>
                            <geom class="visual" mesh="link_15.0"/>
                            <geom class="thumb_distal_collision"/>
                            <body name="th_tip" gravcomp="1">
                              <geom class="thumbtip_visual"/>
                              <geom class="thumbtip_collision"/>
                            </body>
                          </body>
                        </body>
                      </body>
                    </body>
                  </body>

                </body>
              </body>
            </body>
          </body>
        </body>
      </body>
    </body>

    <!-- <body name="mocap" mocap="true" pos="0.59199945 0.13399899 0.26800037" quat="1 0 0 1">
      <geom pos="0 0 0" size="0.01 0.02 0.04" type="box" rgba="1 0 0 1" conaffinity="0" contype="0"/>
    </body> -->
  </worldbody>

  <!-- dex -->
  <contact>
    <exclude body1="palm" body2="ff_base"/>
    <exclude body1="palm" body2="mf_base"/>
    <exclude body1="palm" body2="rf_base"/>
    <exclude body1="palm" body2="th_base"/>
    <exclude body1="palm" body2="th_proximal"/>
  </contact>

</mujoco>