<mujoco model="ur5e_drawer_scene">

  <include file="basic_scene.xml"/>
  <include file="ur5e_with_hand.xml"/>

  <asset>
    <material name="drawer_col" rgba="0.3 0.3 1.0 0.5" shininess="0" specular="0"/>
    <material name="drawer_red" rgba="0.8 0.15 0.15 1" shininess="1" reflectance=".7" specular=".5"/>
    <material name="drawer_white" rgba=".75 .75 .75 1" shininess="1" reflectance=".7" specular=".5"/>
    <material name="drawer_beige" rgba=".4 .65 .4 1" shininess="1" reflectance="1" specular=".5"/>
  </asset>

  <default>
    <default class="drawer_base">
      <joint armature="0.001" damping="2" limited="true"/>
      <geom conaffinity="0" contype="0" group="1" type="mesh"/>
      <position ctrllimited="true" ctrlrange="0 1.57"/>
      <default class="drawer_viz">
        <geom condim="4" type="mesh"/>
      </default>
      <default class="drawer_col">
        <geom conaffinity="1" condim="3" contype="1" group="4" material="drawer_col" solimp="0.99 0.99 0.01" solref="0.01 1"/>
      </default>
    </default>
  </default>

  <asset>
    <mesh file="drawer.stl" name="drawer"/>
    <mesh file="drawercase.stl" name="drawercase"/>
    <mesh file="drawerhandle.stl" name="drawerhandle"/>
  </asset>

  <worldbody>

    <body name="drawer_base" childclass="drawer_base" pos="0.8 -0.3 0" euler="0 0 3.14">
      <body name="drawercase_link" pos="0 0 0.084">
        <geom material="drawer_red" mesh="drawercase"/>
        <geom class="drawer_col" pos="-0.11 0 0" size="0.008 0.1 0.084" type="box" mass=".05"/>
        <geom class="drawer_col" pos="0.11 0 0" size="0.008 0.1 0.084" type="box" mass=".05"/>
        <geom class="drawer_col" pos="0 0.092 -0.008" size="0.102 0.008 0.076" type="box" mass=".05"/>
        <geom class="drawer_col" pos="0 -0.008 -0.07" size="0.102 0.092 0.014" type="box" mass=".05"/>
        <geom class="drawer_col" pos="0 0 0.076" size="0.102 0.1 0.008" type="box" mass=".05"/>
        <body name="drawer_link" pos="0 -0.01 0.006">
          <joint type="slide" range="-0.16 0" axis="0 1 0" name="goal_slidey" pos="0 0 0" damping="10" frictionloss="2"/>
          <geom material="drawer_red" mesh="drawer"/>
          <geom class="drawer_col" pos="0 -0.082 0.008" size="0.1 0.008 0.052" type="box" mass=".04"/>
          <geom class="drawer_col" pos="0 0.082 0.008" size="0.1 0.008 0.052" type="box" mass=".04"/>
          <geom class="drawer_col" pos="-0.092 0 0.008" size="0.008 0.074 0.052" type="box" mass=".04"/>
          <geom class="drawer_col" pos="0.092 0 0.008" size="0.008 0.074 0.052" type="box" mass=".04"/>
          <geom class="drawer_col" pos="0 0 -0.052" size="0.1 0.09 0.008" type="box" mass=".04"/>
          <body name="handle" pos="0 0 0" gravcomp="1">
            <joint type="hinge" name="handle_joint" range="-1.57 1.57" axis="1 0 0" damping="10" stiffness="30"/>
            <geom material="drawer_white" mesh="drawerhandle" pos="0 -0.114 0" name="objGeom"/>
            <geom class="drawer_col" euler="1.571 0 0" pos="-0.05 -0.12 0.0" size="0.009 0.03" type="capsule" mass=".06" friction="0.001 0.005 0.0001"/>
            <geom class="drawer_col" euler="0 1.57 0" pos="0 -0.15 0" size="0.009 0.05" type="capsule" mass=".06" friction="0.001 0.005 0.0001"/>
            <geom class="drawer_col" euler="1.57 0 0" pos="0.05 -0.12 0" size="0.009 0.03" type="capsule" mass=".06" friction="0.001 0.005 0.0001"/>
            <site name="handle_site" pos="0 -0.15 0" size="0.01" rgba="1 0 0 0"/>
          </body>
        </body>
        <site name="target_site" pos="0 -0.3 0.006" size="0.01" rgba="1 0 1 0"/>
      </body>
    </body>


  </worldbody>

</mujoco>
